Workbook

Sheet Qualifier_Analysis_2025-01-01
A1: Qualifier | B1: Allowed as Qualifier | C1: Count as Qualifier | D1: Label | E1: Category | F1: Subcategory | G1: Frequency | H1: Abundance | I1: 1D Diversity | J1: 1D Proportional Diversity | K1: Importantce F * 1DPD | M1: Comment
B2: =SUM(B3:B15000) -> 1850 | C2: =SUM(C3:C15000) -> 1357
A3: P1545 | B3: =_xlfn.XLOOKUP(A3,'Allowed as Qualifiers'!$A$1:$A$1896,'Allowed as Qualifiers'!$B$1:$B$1896,0) -> 1 | C3: =IF(B3=1,1,0)*IF(G3>0,1,0) -> 1 | D3: series ordinal | E3: A | F3: Sequence | G3: 198557380 | H3: =_xlfn.XLOOKUP(A3,'Diversity Analysis'!$A$2:$A$2366,'Diversity Analysis'!$F$2:$F$2366,"") -> 592 | I3: 2.2972161 | J3: 60.986634 | K3: =G3/1000000*J3 -> 12109.346
A4: P1810 | B4: =_xlfn.XLOOKUP(A4,'Allowed as Qualifiers'!$A$1:$A$1896,'Allowed as Qualifiers'!$B$1:$B$1896,0) -> 1 | C4: =IF(B4=1,1,0)*IF(G4>0,1,0) -> 1 | D4: subject named as | E4: A | F4: Provenance | G4: 6480845 | H4: =_xlfn.XLOOKUP(A4,'Diversity Analysis'!$A$2:$A$2366,'Diversity Analysis'!$F$2:$F$2366,"") -> 4409 | I4: 74.628448 | J4: 716.95669 | K4: =G4/1000000*J4 -> 4646.4852 | M4: mostly for Ext. Obj. Desc. execpt described by source
A5: P585 | B5: =_xlfn.XLOOKUP(A5,'Allowed as Qualifiers'!$A$1:$A$1896,'Allowed as Qualifiers'!$B$1:$B$1896,0) -> 1 | C5: =IF(B5=1,1,0)*IF(G5>0,1,0) -> 1 | D5: point in time | E5: Ctxt | F5: Time | G5: 14667663 | H5: =_xlfn.XLOOKUP(A5,'Diversity Analysis'!$A$2:$A$2366,'Diversity Analysis'!$F$2:$F$2366,"") -> 1510 | I5: 22.605733 | J5: 292.34028 | K5: =G5/1000000*J5 -> 4287.9487 | R5: Time | S5: =COUNTIF($F$3:$F$53,R5) -> 4 | T5: =COUNTIF($F$3:$F$306,R5) -> 8
A6: P580 | B6: =_xlfn.XLOOKUP(A6,'Allowed as Qualifiers'!$A$1:$A$1896,'Allowed as Qualifiers'!$B$1:$B$1896,0) -> 1 | C6: =IF(B6=1,1,0)*IF(G6>0,1,0) -> 1 | D6: start time | E6: Ctxt | F6: Time | G6: 11563055 | H6: =_xlfn.XLOOKUP(A6,'Diversity Analysis'!$A$2:$A$2366,'Diversity Analysis'!$F$2:$F$2366,"") -> 1727 | I6: 24.126413 | J6: 300.22414 | K6: =G6/1000000*J6 -> 3471.5082 | R6: Space | S6: =COUNTIF($F$3:$F$53,R6) -> 1 | T6: =COUNTIF($F$3:$F$306,R6) -> 4
A7: P1932 | B7: =_xlfn.XLOOKUP(A7,'Allowed as Qualifiers'!$A$1:$A$1896,'Allowed as Qualifiers'!$B$1:$B$1896,0) -> 1 | C7: =IF(B7=1,1,0)*IF(G7>0,1,0) -> 1 | D7: object named as | E7: A | F7: Provenance | G7: 22167461 | H7: =_xlfn.XLOOKUP(A7,'Diversity Analysis'!$A$2:$A$2366,'Diversity Analysis'!$F$2:$F$2366,"") -> 1096 | I7: 1.6783922 | J7: 75.626808 | K7: =G7/1000000*J7 -> 1676.4543 | R7: Subject Modifier | S7: =COUNTIF($F$3:$F$53,R7) -> 1 | T7: =COUNTIF($F$3:$F$306,R7) -> 4
A8: P582 | B8: =_xlfn.XLOOKUP(A8,'Allowed as Qualifiers'!$A$1:$A$1896,'Allowed as Qualifiers'!$B$1:$B$1896,0) -> 1 | C8: =IF(B8=1,1,0)*IF(G8>0,1,0) -> 1 | D8: end time | E8: Ctxt | F8: Time | G8: 5440957 | H8: =_xlfn.XLOOKUP(A8,'Diversity Analysis'!$A$2:$A$2366,'Diversity Analysis'!$F$2:$F$2366,"") -> 1483 | I8: 16.736172 | J8: 216.79831 | K8: =G8/1000000*J8 -> 1179.5903 | R8: Epistemic | S8: =COUNTIF($F$3:$F$53,R8) -> 1 | T8: =COUNTIF($F$3:$F$306,R8) -> 3
A9: P459 | B9: =_xlfn.XLOOKUP(A9,'Allowed as Qualifiers'!$A$1:$A$1896,'Allowed as Qualifiers'!$B$1:$B$1896,0) -> 1 | C9: =IF(B9=1,1,0)*IF(G9>0,1,0) -> 1 | D9: determination method or standard | E9: A | F9: Provenance | G9: 9624947 | H9: =_xlfn.XLOOKUP(A9,'Diversity Analysis'!$A$2:$A$2366,'Diversity Analysis'!$F$2:$F$2366,"") -> 358 | I9: 9.3376637 | J9: 75.433105 | K9: =G9/1000000*J9 -> 726.03963 | R9: Uncertainty Quantification | S9: =COUNTIF($F$3:$F$53,R9) -> 2 | T9: =COUNTIF($F$3:$F$306,R9) -> 5
A10: P407 | B10: =_xlfn.XLOOKUP(A10,'Allowed as Qualifiers'!$A$1:$A$1896,'Allowed as Qualifiers'!$B$1:$B$1896,0) -> 1 | C10: =IF(B10=1,1,0)*IF(G10>0,1,0) -> 1 | D10: language of work or name | E10: A | F10: External Object Description | G10: 2207095 | H10: =_xlfn.XLOOKUP(A10,'Diversity Analysis'!$A$2:$A$2366,'Diversity Analysis'!$F$2:$F$2366,"") -> 1485 | I10: 9.4893184 | J10: 155.43341 | K10: =G10/1000000*J10 -> 343.0563 | M10: when the value is a reference (URL, ID, …) description of the referent | R10: Structured Value | S10: =COUNTIF($F$3:$F$53,R10) -> 7 | T10: =COUNTIF($F$3:$F$306,R10) -> 17
A11: P518 | B11: =_xlfn.XLOOKUP(A11,'Allowed as Qualifiers'!$A$1:$A$1896,'Allowed as Qualifiers'!$B$1:$B$1896,0) -> 1 | C11: =IF(B11=1,1,0)*IF(G11>0,1,0) -> 1 | D11: applies to part | E11: Ctxt | F11: Subject Modifier | G11: 1791730 | H11: =_xlfn.XLOOKUP(A11,'Diversity Analysis'!$A$2:$A$2366,'Diversity Analysis'!$F$2:$F$2366,"") -> 1662 | I11: 20.354618 | J11: 189.55654 | K11: =G11/1000000*J11 -> 339.63414 | R11: Meta | S11: =COUNTIF($F$3:$F$53,R11) -> 0 | T11: =COUNTIF($F$3:$F$306,R11) -> 18
A12: P3831 | B12: =_xlfn.XLOOKUP(A12,'Allowed as Qualifiers'!$A$1:$A$1896,'Allowed as Qualifiers'!$B$1:$B$1896,0) -> 1 | C12: =IF(B12=1,1,0)*IF(G12>0,1,0) -> 1 | D12: object of statement has role | E12: A | F12: Object/Subject Statement Relation | G12: 1953878 | H12: =_xlfn.XLOOKUP(A12,'Diversity Analysis'!$A$2:$A$2366,'Diversity Analysis'!$F$2:$F$2366,"") -> 923 | I12: 31.761936 | J12: 96.789859 | K12: =G12/1000000*J12 -> 189.11558 | R12: Sequence | S12: =COUNTIF($F$3:$F$53,R12) -> 3 | T12: =COUNTIF($F$3:$F$306,R12) -> 7
A13: P1013 | B13: =_xlfn.XLOOKUP(A13,'Allowed as Qualifiers'!$A$1:$A$1896,'Allowed as Qualifiers'!$B$1:$B$1896,0) -> 1 | C13: =IF(B13=1,1,0)*IF(G13>0,1,0) -> 1 | D13: criterion used | E13: A | F13: Sub-Property or Value | G13: 2174032 | H13: =_xlfn.XLOOKUP(A13,'Diversity Analysis'!$A$2:$A$2366,'Diversity Analysis'!$F$2:$F$2366,"") -> 464 | I13: 10.596544 | J13: 52.808107 | K13: =G13/1000000*J13 -> 114.80651 | M13: Sub-Property or Value indicator (population/are, opposite/criterion, | R13: Provenance | S13: =COUNTIF($F$3:$F$53,R13) -> 5 | T13: =COUNTIF($F$3:$F$306,R13) -> 12
A14: P577 | B14: =_xlfn.XLOOKUP(A14,'Allowed as Qualifiers'!$A$1:$A$1896,'Allowed as Qualifiers'!$B$1:$B$1896,0) -> 1 | C14: =IF(B14=1,1,0)*IF(G14>0,1,0) -> 1 | D14: publication date | E14: A | F14: External Object Description | G14: 2030479 | H14: =_xlfn.XLOOKUP(A14,'Diversity Analysis'!$A$2:$A$2366,'Diversity Analysis'!$F$2:$F$2366,"") -> 526 | I14: 5.3697342 | J14: 53.171989 | K14: =G14/1000000*J14 -> 107.96461 | M14: usage in cites word and published in is wrong | R14: Causality | S14: =COUNTIF($F$3:$F$53,R14) -> 1 | T14: =COUNTIF($F$3:$F$306,R14) -> 4
A15: P972 | B15: =_xlfn.XLOOKUP(A15,'Allowed as Qualifiers'!$A$1:$A$1896,'Allowed as Qualifiers'!$B$1:$B$1896,0) -> 1 | C15: =IF(B15=1,1,0)*IF(G15>0,1,0) -> 1 | D15: catalog | E15: Struct | F15: Structured Value | G15: 24051714 | H15: =_xlfn.XLOOKUP(A15,'Diversity Analysis'!$A$2:$A$2366,'Diversity Analysis'!$F$2:$F$2366,"") -> 60 | I15: 1.0265834 | J15: 4.3282113 | K15: =G15/1000000*J15 -> 104.1009 | M15: mandatory annotation for catalog_code | R15: Object/Subject Statement Relation | S15: =COUNTIF($F$3:$F$53,R15) -> 2 | T15: =COUNTIF($F$3:$F$306,R15) -> 5
A16: P1227 | B16: =_xlfn.XLOOKUP(A16,'Allowed as Qualifiers'!$A$1:$A$1896,'Allowed as Qualifiers'!$B$1:$B$1896,0) -> 1 | C16: =IF(B16=1,1,0)*IF(G16>0,1,0) -> 1 | D16: astronomical filter | E16: Struct | F16: Structured Value | G16: 33145675 | H16: =_xlfn.XLOOKUP(A16,'Diversity Analysis'!$A$2:$A$2366,'Diversity Analysis'!$F$2:$F$2366,"") -> 4 | I16: 1.0000175 | J16: 1.9226712 | K16: =G16/1000000*J16 -> 63.728236 | M16: mandatory for star magnitude & color index | R16: Sub-Property or Value | S16: =COUNTIF($F$3:$F$53,R16) -> 4 | T16: =COUNTIF($F$3:$F$306,R16) -> 9
A17: P2701 | B17: =_xlfn.XLOOKUP(A17,'Allowed as Qualifiers'!$A$1:$A$1896,'Allowed as Qualifiers'!$B$1:$B$1896,0) -> 1 | C17: =IF(B17=1,1,0)*IF(G17>0,1,0) -> 1 | D17: file format | E17: A | F17: External Object Description | G17: 3146867 | H17: =_xlfn.XLOOKUP(A17,'Diversity Analysis'!$A$2:$A$2366,'Diversity Analysis'!$F$2:$F$2366,"") -> 94 | I17: 1.131255 | J17: 11.368601 | K17: =G17/1000000*J17 -> 35.775477 | R17: External Object Description | S17: =COUNTIF($F$3:$F$53,R17) -> 11 | T17: =COUNTIF($F$3:$F$306,R17) -> 49
A18: P1001 | B18: =_xlfn.XLOOKUP(A18,'Allowed as Qualifiers'!$A$1:$A$1896,'Allowed as Qualifiers'!$B$1:$B$1896,0) -> 1 | C18: =IF(B18=1,1,0)*IF(G18>0,1,0) -> 1 | D18: applies to jurisdiction | E18: Ctxt | F18: Space | G18: 1433042 | H18: =_xlfn.XLOOKUP(A18,'Diversity Analysis'!$A$2:$A$2366,'Diversity Analysis'!$F$2:$F$2366,"") -> 364 | I18: 2.513847 | J18: 20.255587 | K18: =G18/1000000*J18 -> 29.027106 | R18: Other Additional | S18: =COUNTIF($F$3:$F$53,R18) -> 8 | T18: =COUNTIF($F$3:$F$306,R18) -> 155
A19: P2868 | B19: =_xlfn.XLOOKUP(A19,'Allowed as Qualifiers'!$A$1:$A$1896,'Allowed as Qualifiers'!$B$1:$B$1896,0) -> 1 | C19: =IF(B19=1,1,0)*IF(G19>0,1,0) -> 1 | D19: subject has role | E19: A | F19: Object/Subject Statement Relation | G19: 872919 | H19: =_xlfn.XLOOKUP(A19,'Diversity Analysis'!$A$2:$A$2366,'Diversity Analysis'!$F$2:$F$2366,"") -> 521 | I19: 10.812686 | J19: 31.810434 | K19: =G19/1000000*J19 -> 27.767933 | S19: =SUM(S5:S18) -> 50 | T19: =SUM(T5:T18) -> 300
A20: P7452 | B20: =_xlfn.XLOOKUP(A20,'Allowed as Qualifiers'!$A$1:$A$1896,'Allowed as Qualifiers'!$B$1:$B$1896,0) -> 1 | C20: =IF(B20=1,1,0)*IF(G20>0,1,0) -> 1 | D20: reason for preferred rank | E20: A | F20: Provenance | G20: 277968 | H20: =_xlfn.XLOOKUP(A20,'Diversity Analysis'!$A$2:$A$2366,'Diversity Analysis'!$F$2:$F$2366,"") -> 876 | I20: 9.4578249 | J20: 93.841605 | K20: =G20/1000000*J20 -> 26.084963
A21: P1480 | B21: =_xlfn.XLOOKUP(A21,'Allowed as Qualifiers'!$A$1:$A$1896,'Allowed as Qualifiers'!$B$1:$B$1896,0) -> 1 | C21: =IF(B21=1,1,0)*IF(G21>0,1,0) -> 1 | D21: sourcing circumstances | E21: E/U | F21: Epistemic | G21: 397143 | H21: =_xlfn.XLOOKUP(A21,'Diversity Analysis'!$A$2:$A$2366,'Diversity Analysis'!$F$2:$F$2366,"") -> 753 | I21: 7.5652949 | J21: 64.251495 | K21: =G21/1000000*J21 -> 25.517031 | M21: truth of statement, accuracy, reliability, confidence, precision, certainty, validity, 82% value = circa
A22: P2093 | B22: =_xlfn.XLOOKUP(A22,'Allowed as Qualifiers'!$A$1:$A$1896,'Allowed as Qualifiers'!$B$1:$B$1896,0) -> 1 | C22: =IF(B22=1,1,0)*IF(G22>0,1,0) -> 1 | D22: author name string | E22: A | F22: External Object Description | G22: 846447 | H22: =_xlfn.XLOOKUP(A22,'Diversity Analysis'!$A$2:$A$2366,'Diversity Analysis'!$F$2:$F$2366,"") -> 193 | I22: 2.1734145 | J22: 27.577817 | K22: =G22/1000000*J22 -> 23.343161
A23: P805 | B23: =_xlfn.XLOOKUP(A23,'Allowed as Qualifiers'!$A$1:$A$1896,'Allowed as Qualifiers'!$B$1:$B$1896,0) -> 1 | C23: =IF(B23=1,1,0)*IF(G23>0,1,0) -> 1 | D23: statement is subject of | E23: A | F23: Other Additional | G23: 665040 | H23: =_xlfn.XLOOKUP(A23,'Diversity Analysis'!$A$2:$A$2366,'Diversity Analysis'!$F$2:$F$2366,"") -> 614 | I23: 4.8361258 | J23: 32.659876 | K23: =G23/1000000*J23 -> 21.720124
A24: P642 | B24: =_xlfn.XLOOKUP(A24,'Allowed as Qualifiers'!$A$1:$A$1896,'Allowed as Qualifiers'!$B$1:$B$1896,0) -> 1 | C24: =IF(B24=1,1,0)*IF(G24>0,1,0) -> 1 | D24: of | F24: N/A | G24: 418350 | H24: =_xlfn.XLOOKUP(A24,'Diversity Analysis'!$A$2:$A$2366,'Diversity Analysis'!$F$2:$F$2366,"") -> 662 | I24: 8.2660494 | J24: 51.265861 | K24: =G24/1000000*J24 -> 21.447073 | M24: deprecated
A25: P1352 | B25: =_xlfn.XLOOKUP(A25,'Allowed as Qualifiers'!$A$1:$A$1896,'Allowed as Qualifiers'!$B$1:$B$1896,0) -> 1 | C25: =IF(B25=1,1,0)*IF(G25>0,1,0) -> 1 | D25: ranking | E25: A | F25: Other Additional | G25: 1089666 | H25: =_xlfn.XLOOKUP(A25,'Diversity Analysis'!$A$2:$A$2366,'Diversity Analysis'!$F$2:$F$2366,"") -> 89 | I25: 7.0075925 | J25: 19.131755 | K25: =G25/1000000*J25 -> 20.847223
A26: P478 | B26: =_xlfn.XLOOKUP(A26,'Allowed as Qualifiers'!$A$1:$A$1896,'Allowed as Qualifiers'!$B$1:$B$1896,0) -> 1 | C26: =IF(B26=1,1,0)*IF(G26>0,1,0) -> 1 | D26: volume | E26: A | F26: Sub-Property or Value | G26: 1075074 | H26: =_xlfn.XLOOKUP(A26,'Diversity Analysis'!$A$2:$A$2366,'Diversity Analysis'!$F$2:$F$2366,"") -> 199 | I26: 2.8254275 | J26: 14.614536 | K26: =G26/1000000*J26 -> 15.711707 | M26: for published in, with cites word = error
A27: P1552 | B27: =_xlfn.XLOOKUP(A27,'Allowed as Qualifiers'!$A$1:$A$1896,'Allowed as Qualifiers'!$B$1:$B$1896,0) -> 1 | C27: =IF(B27=1,1,0)*IF(G27>0,1,0) -> 1 | D27: has characteristic | E27: A | F27: External Object Description | G27: 210067 | H27: =_xlfn.XLOOKUP(A27,'Diversity Analysis'!$A$2:$A$2366,'Diversity Analysis'!$F$2:$F$2366,"") -> 747 | I27: 12.657377 | J27: 72.728797 | K27: =G27/1000000*J27 -> 15.27792
A28: P1326 | B28: =_xlfn.XLOOKUP(A28,'Allowed as Qualifiers'!$A$1:$A$1896,'Allowed as Qualifiers'!$B$1:$B$1896,0) -> 1 | C28: =IF(B28=1,1,0)*IF(G28>0,1,0) -> 1 | D28: latest date | E28: E/U | F28: Uncertainty Quantification | G28: 415023 | H28: =_xlfn.XLOOKUP(A28,'Diversity Analysis'!$A$2:$A$2366,'Diversity Analysis'!$F$2:$F$2366,"") -> 263 | I28: 3.6373913 | J28: 34.56331 | K28: =G28/1000000*J28 -> 14.344569 | M28: qualifier for date properties, indicates uncertainty
A29: P6954 | B29: =_xlfn.XLOOKUP(A29,'Allowed as Qualifiers'!$A$1:$A$1896,'Allowed as Qualifiers'!$B$1:$B$1896,0) -> 1 | C29: =IF(B29=1,1,0)*IF(G29>0,1,0) -> 1 | D29: online access status | E29: A | F29: External Object Description | G29: 1939603 | H29: =_xlfn.XLOOKUP(A29,'Diversity Analysis'!$A$2:$A$2366,'Diversity Analysis'!$F$2:$F$2366,"") -> 69 | I29: 1.0140949 | J29: 6.0812224 | K29: =G29/1000000*J29 -> 11.795157
A30: P304 | B30: =_xlfn.XLOOKUP(A30,'Allowed as Qualifiers'!$A$1:$A$1896,'Allowed as Qualifiers'!$B$1:$B$1896,0) -> 1 | C30: =IF(B30=1,1,0)*IF(G30>0,1,0) -> 1 | D30: page(s) | E30: A | F30: Sub-Property or Value | G30: 1479029 | H30: =_xlfn.XLOOKUP(A30,'Diversity Analysis'!$A$2:$A$2366,'Diversity Analysis'!$F$2:$F$2366,"") -> 204 | I30: 3.0792176 | J30: 7.9747331 | K30: =G30/1000000*J30 -> 11.794862 | M30: for published in, with cites word = error
A31: P2096 | B31: =_xlfn.XLOOKUP(A31,'Allowed as Qualifiers'!$A$1:$A$1896,'Allowed as Qualifiers'!$B$1:$B$1896,0) -> 1 | C31: =IF(B31=1,1,0)*IF(G31>0,1,0) -> 1 | D31: media legend | E31: A | F31: External Object Description | G31: 289612 | H31: =_xlfn.XLOOKUP(A31,'Diversity Analysis'!$A$2:$A$2366,'Diversity Analysis'!$F$2:$F$2366,"") -> 218 | I31: 1.5512387 | J31: 39.727214 | K31: =G31/1000000*J31 -> 11.505478 | M31: for several image … predicates
A32: P195 | B32: =_xlfn.XLOOKUP(A32,'Allowed as Qualifiers'!$A$1:$A$1896,'Allowed as Qualifiers'!$B$1:$B$1896,0) -> 1 | C32: =IF(B32=1,1,0)*IF(G32>0,1,0) -> 1 | D32: collection | E32: Struct | F32: Structured Value | G32: 1800053 | H32: =_xlfn.XLOOKUP(A32,'Diversity Analysis'!$A$2:$A$2366,'Diversity Analysis'!$F$2:$F$2366,"") -> 111 | I32: 1.2277708 | J32: 6.0430723 | K32: =G32/1000000*J32 -> 10.87785 | M32: mandatory annotation for inventory_number
A33: P400 | B33: =_xlfn.XLOOKUP(A33,'Allowed as Qualifiers'!$A$1:$A$1896,'Allowed as Qualifiers'!$B$1:$B$1896,0) -> 1 | C33: =IF(B33=1,1,0)*IF(G33>0,1,0) -> 1 | D33: platform | E33: A | F33: External Object Description | G33: 228447 | H33: =_xlfn.XLOOKUP(A33,'Diversity Analysis'!$A$2:$A$2366,'Diversity Analysis'!$F$2:$F$2366,"") -> 266 | I33: 17.246737 | J33: 47.385684 | K33: =G33/1000000*J33 -> 10.825117
A34: P2699 | B34: =_xlfn.XLOOKUP(A34,'Allowed as Qualifiers'!$A$1:$A$1896,'Allowed as Qualifiers'!$B$1:$B$1896,0) -> 1 | C34: =IF(B34=1,1,0)*IF(G34>0,1,0) -> 1 | D34: URL | E34: A | F34: Other Additional | G34: 352080 | H34: =_xlfn.XLOOKUP(A34,'Diversity Analysis'!$A$2:$A$2366,'Diversity Analysis'!$F$2:$F$2366,"") -> 460 | I34: 4.6664887 | J34: 30.639212 | K34: =G34/1000000*J34 -> 10.787454
A35: P6259 | B35: =_xlfn.XLOOKUP(A35,'Allowed as Qualifiers'!$A$1:$A$1896,'Allowed as Qualifiers'!$B$1:$B$1896,0) -> 1 | C35: =IF(B35=1,1,0)*IF(G35>0,1,0) -> 1 | D35: epoch | E35: Struct | F35: Structured Value | G35: 987965 | H35: =_xlfn.XLOOKUP(A35,'Diversity Analysis'!$A$2:$A$2366,'Diversity Analysis'!$F$2:$F$2366,"") -> 19 | I35: 10.012824 | J35: 9.9223814 | K35: =G35/1000000*J35 -> 9.8029655
A36: P1534 | B36: =_xlfn.XLOOKUP(A36,'Allowed as Qualifiers'!$A$1:$A$1896,'Allowed as Qualifiers'!$B$1:$B$1896,0) -> 1 | C36: =IF(B36=1,1,0)*IF(G36>0,1,0) -> 1 | D36: end cause | E36: A | F36: Causality | G36: 204973 | H36: =_xlfn.XLOOKUP(A36,'Diversity Analysis'!$A$2:$A$2366,'Diversity Analysis'!$F$2:$F$2366,"") -> 339 | I36: 8.2297455 | J36: 43.037466 | K36: =G36/1000000*J36 -> 8.8215186
A37: P1319 | B37: =_xlfn.XLOOKUP(A37,'Allowed as Qualifiers'!$A$1:$A$1896,'Allowed as Qualifiers'!$B$1:$B$1896,0) -> 1 | C37: =IF(B37=1,1,0)*IF(G37>0,1,0) -> 1 | D37: earliest date | E37: E/U | F37: Uncertainty Quantification | G37: 365280 | H37: =_xlfn.XLOOKUP(A37,'Diversity Analysis'!$A$2:$A$2366,'Diversity Analysis'!$F$2:$F$2366,"") -> 243 | I37: 2.6108141 | J37: 22.643891 | K37: =G37/1000000*J37 -> 8.2713603 | M37: qualifier for date properties, indicates uncertainty
A38: P1057 | B38: =_xlfn.XLOOKUP(A38,'Allowed as Qualifiers'!$A$1:$A$1896,'Allowed as Qualifiers'!$B$1:$B$1896,0) -> 1 | C38: =IF(B38=1,1,0)*IF(G38>0,1,0) -> 1 | D38: chromosome | E38: Struct | F38: Structured Value | G38: 2776319 | H38: =_xlfn.XLOOKUP(A38,'Diversity Analysis'!$A$2:$A$2366,'Diversity Analysis'!$F$2:$F$2366,"") -> 10 | I38: 2.9742531 | J38: 2.9780684 | K38: =G38/1000000*J38 -> 8.2680679
A39: P3744 | B39: =_xlfn.XLOOKUP(A39,'Allowed as Qualifiers'!$A$1:$A$1896,'Allowed as Qualifiers'!$B$1:$B$1896,0) -> 1 | C39: =IF(B39=1,1,0)*IF(G39>0,1,0) -> 1 | D39: number of subscribers | E39: A | F39: External Object Description | G39: 341490 | H39: =_xlfn.XLOOKUP(A39,'Diversity Analysis'!$A$2:$A$2366,'Diversity Analysis'!$F$2:$F$2366,"") -> 128 | I39: 3.2567672 | J39: 23.155297 | K39: =G39/1000000*J39 -> 7.9073024
A40: P155 | B40: =_xlfn.XLOOKUP(A40,'Allowed as Qualifiers'!$A$1:$A$1896,'Allowed as Qualifiers'!$B$1:$B$1896,0) -> 1 | C40: =IF(B40=1,1,0)*IF(G40>0,1,0) -> 1 | D40: follows | E40: A | F40: Sequence | G40: 1030678 | H40: =_xlfn.XLOOKUP(A40,'Diversity Analysis'!$A$2:$A$2366,'Diversity Analysis'!$F$2:$F$2366,"") -> 164 | I40: 3.5201501 | J40: 7.5203741 | K40: =G40/1000000*J40 -> 7.7510841
...

Sheet Allowed as Qualifiers
A1: P263 | B1: 1
A2: P264 | B2: 1
A3: P275 | B3: 1
A4: P276 | B4: 1
A5: P281 | B5: 1
A6: P282 | B6: 1
A7: P287 | B7: 1
A8: P286 | B8: 1
A9: P289 | B9: 1
A10: P291 | B10: 1
A11: P296 | B11: 1
A12: P305 | B12: 1
... A1896: P248 | B1896: 1

Sheet Diversity Analysis
A1: Qualifer | B1: Name | C1: Frequency | D1: Sh. Diversity | E1: Sh. Prop. Diversity | F1: Abundance | G1: Importance Score
A2: P1545 | B2: series ordinal | C2: 198557380 | D2: 2.2972161 | E2: 60.986634 | F2: 592 | G2: 1.2109346e+10
A3: P1227 | B3: astronomical filter | C3: 33145675 | D3: 1.0000175 | E3: 1.9226712 | F3: 4 | G3: 63728236
A4: P972 | B4: catalog | C4: 24051714 | D4: 1.0265834 | E4: 4.3282113 | F4: 60 | G4: 1.041009e+08
A5: P1932 | B5: object named as | C5: 22167461 | D5: 1.6783922 | E5: 75.626808 | F5: 1096 | G5: 1.6764543e+09
A6: P585 | B6: point in time | C6: 14667663 | D6: 22.605733 | E6: 292.34028 | F6: 1510 | G6: 4.2879487e+09
A7: P580 | B7: start time | C7: 11563055 | D7: 24.126413 | E7: 300.22414 | F7: 1727 | G7: 3.4715082e+09
A8: P459 | B8: determination method or standard | C8: 9624947 | D8: 9.3376637 | E8: 75.433105 | F8: 358 | G8: 7.2603963e+08
A9: P1810 | B9: subject named as | C9: 6480845 | D9: 74.628448 | E9: 716.95669 | F9: 4409 | G9: 4.6464852e+09
A10: P582 | B10: end time | C10: 5440957 | D10: 16.736172 | E10: 216.79831 | F10: 1483 | G10: 1.1795903e+09
A11: P703 | B11: found in taxon | C11: 4361971 | D11: 1.0007117 | E11: 1.0385861 | F11: 20 | G11: 4530282.2
A12: P2701 | B12: file format | C12: 3146867 | D12: 1.131255 | E12: 11.368601 | F12: 94 | G12: 35775477
A13: P1057 | B13: chromosome | C13: 2776319 | D13: 2.9742531 | E13: 2.9780684 | F13: 10 | G13: 8268067.9
... A2366: P8275 | B2366: position in biological sequence | C2366: 1 | D2366: 1 | E2366: 1 | F2366: 1 | G2366: 1

Sheet Distribution in Categories
C5: Category | D5: In Top 50 | E5: In Top 300
C6: Time | D6: =COUNTIF('Qualifier_Analysis_2025-01-01'!$F$3:$F$53,C6) -> 4 | E6: =COUNTIF('Qualifier_Analysis_2025-01-01'!$F$3:$F$306,C6) -> 8
C7: Space | D7: =COUNTIF('Qualifier_Analysis_2025-01-01'!$F$3:$F$53,C7) -> 1 | E7: =COUNTIF('Qualifier_Analysis_2025-01-01'!$F$3:$F$306,C7) -> 4
C8: Subject Modifier | D8: =COUNTIF('Qualifier_Analysis_2025-01-01'!$F$3:$F$53,C8) -> 1 | E8: =COUNTIF('Qualifier_Analysis_2025-01-01'!$F$3:$F$306,C8) -> 4
C9: Epistemic | D9: =COUNTIF('Qualifier_Analysis_2025-01-01'!$F$3:$F$53,C9) -> 1 | E9: =COUNTIF('Qualifier_Analysis_2025-01-01'!$F$3:$F$306,C9) -> 3
C10: Uncertainty Quantification | D10: =COUNTIF('Qualifier_Analysis_2025-01-01'!$F$3:$F$53,C10) -> 2 | E10: =COUNTIF('Qualifier_Analysis_2025-01-01'!$F$3:$F$306,C10) -> 5
C11: Structured Value | D11: =COUNTIF('Qualifier_Analysis_2025-01-01'!$F$3:$F$53,C11) -> 7 | E11: =COUNTIF('Qualifier_Analysis_2025-01-01'!$F$3:$F$306,C11) -> 17
C12: Meta | D12: =COUNTIF('Qualifier_Analysis_2025-01-01'!$F$3:$F$53,C12) -> 0 | E12: =COUNTIF('Qualifier_Analysis_2025-01-01'!$F$3:$F$306,C12) -> 18
C13: Sequence | D13: =COUNTIF('Qualifier_Analysis_2025-01-01'!$F$3:$F$53,C13) -> 3 | E13: =COUNTIF('Qualifier_Analysis_2025-01-01'!$F$3:$F$306,C13) -> 7
C14: Provenance | D14: =COUNTIF('Qualifier_Analysis_2025-01-01'!$F$3:$F$53,C14) -> 5 | E14: =COUNTIF('Qualifier_Analysis_2025-01-01'!$F$3:$F$306,C14) -> 12
C15: Causality | D15: =COUNTIF('Qualifier_Analysis_2025-01-01'!$F$3:$F$53,C15) -> 1 | E15: =COUNTIF('Qualifier_Analysis_2025-01-01'!$F$3:$F$306,C15) -> 4
C16: Object/Subject Statement Relation | D16: =COUNTIF('Qualifier_Analysis_2025-01-01'!$F$3:$F$53,C16) -> 2 | E16: =COUNTIF('Qualifier_Analysis_2025-01-01'!$F$3:$F$306,C16) -> 5
C17: Sub-Property or Value | D17: =COUNTIF('Qualifier_Analysis_2025-01-01'!$F$3:$F$53,C17) -> 4 | E17: =COUNTIF('Qualifier_Analysis_2025-01-01'!$F$3:$F$306,C17) -> 9
... C19: Other Additional | D19: =COUNTIF('Qualifier_Analysis_2025-01-01'!$F$3:$F$53,C19) -> 8 | E19: =COUNTIF('Qualifier_Analysis_2025-01-01'!$F$3:$F$306,C19) -> 155
D20: =SUM(D6:D19) -> 50 | E20: =SUM(E6:E19) -> 300
